Workbook

Sheet Capa
B3: FORNIX
B4: Base Mestra de Fornecedores — Polo Atacadista do Brás (SP)
B5: Compre direto da fábrica. Sem intermediários. Mais margem no Shopee, Mercado Livre e Instagram.
B7: 1019 | D7: 6
B8: Fornecedores Únicos | D8: Polos / Galerias Mapeados
B11: 22 | D11: 05/08/2026
B12: Categorias de Produto | D12: Atualizado em
B16: Polos incluídos nesta base
B17: Polo / Galeria | F17: Fornecedores
B18: Galeria Pagé | F18: 287
B19: Shopping Total Brás | F19: 255
B20: Shopping Canindé | F20: 193
B21: Shopping Porto Brás | F21: 157
B22: Shopping All Brás | F22: 105
B23: O Melhor do Brás (Diretório) | F23: 22
B24: TOTAL GERAL (base única, sem duplicidades) | F24: =SUM(F18:F23) -> 1019
B27: Como navegar nesta pasta de trabalho
B28: ▸ Base Completa
B29: Todos os 1.0xx fornecedores, filtráveis por polo, categoria e segmento. Use os filtros do cabeçalho.
B30: ▸ Painel por Categoria
B31: Ranking das categorias de produto com mais fornecedores mapeados.
B32: ▸ Painel por Polo
B33: Comparativo do número de fornecedores por shopping/galeria.
B34: ▸ Total Brás / Pagé / Canindé / Porto Brás / All Brás / O Melhor do Brás
B35: Uma aba por polo, já filtrada, pronta para prospecção direcionada.
B36: ▸ Como Usar
B37: Boas práticas de contato, checklist de prospecção e avisos importantes.

Sheet Como Usar
B2: Como usar a base FORNIX
B4: 1. Filtre antes de abordar
B5: Na aba 'Base Completa', use os filtros do cabeçalho (ícone de seta em cada coluna) para cruzar Categoria + Polo e montar sua lista de prospecção do dia. Evite contatar a base inteira de uma vez.
B7: 2. Aborde pelo WhatsApp de forma direta e educada
B8: Apresente-se, diga que encontrou a loja no polo do Brás e pergunte sobre condições de atacado, pedido mínimo e se enviam para todo o Brasil. Fornecedores respondem melhor a mensagens objetivas do que a textos longos.
B10: 3. Confirme sempre antes de fechar pedido
B11: Esta base é uma lista de contatos para prospecção — não é uma garantia de preço, estoque ou qualidade. Confirme fotos reais do produto, prazo de envio e política de troca antes de pagar. Prefira fornecedores com Instagram ativo e avaliações de outros lojistas.
B13: 4. Priorize por volume de fornecedores
B14: Use a aba 'Painel por Categoria' para identificar onde há mais oferta (ex.: Moda Feminina e Eletrônicos concentram a maior parte da base) e a aba 'Painel por Polo' para escolher qual shopping visitar ou prospectar primeiro.
B16: Avisos importantes
B17: • Os dados foram coletados dos sites oficiais dos polos e são atualizados periodicamente — nomes de loja, telefone e Instagram podem mudar sem aviso.
B18: • Os links de WhatsApp seguem o padrão wa.me e abrem diretamente a conversa; a FORNIX não intermedia negociações, pagamentos ou entregas.
... B22: Dúvidas ou suporte: fale com a equipe FORNIX pelo canal onde você adquiriu esta base.

Sheet Painel por Categoria
B2: Fornecedores por Categoria de Produto
B4: Categoria | C4: Fornecedores | D4: % da Base
B5: Moda Feminina | C5: =COUNTIF('Base Completa'!C2:C1020,B5) -> 482 | D5: =C5/SUM($C$5:$C$26) -> 0.47301276
B6: Eletrônicos e Celulares | C6: =COUNTIF('Base Completa'!C2:C1020,B6) -> 115 | D6: =C6/SUM($C$5:$C$26) -> 0.11285574
B7: Moda Feminina Plus Size | C7: =COUNTIF('Base Completa'!C2:C1020,B7) -> 75 | D7: =C7/SUM($C$5:$C$26) -> 0.07360157
B8: Acessórios e Bijuterias | C8: =COUNTIF('Base Completa'!C2:C1020,B8) -> 65 | D8: =C8/SUM($C$5:$C$26) -> 0.063788027
B9: Moda Jeans | C9: =COUNTIF('Base Completa'!C2:C1020,B9) -> 52 | D9: =C9/SUM($C$5:$C$26) -> 0.051030422
B10: Relógios e Óculos | C10: =COUNTIF('Base Completa'!C2:C1020,B10) -> 31 | D10: =C10/SUM($C$5:$C$26) -> 0.030421982
B11: Perfumaria e Cosméticos | C11: =COUNTIF('Base Completa'!C2:C1020,B11) -> 31 | D11: =C11/SUM($C$5:$C$26) -> 0.030421982
B12: Variedades | C12: =COUNTIF('Base Completa'!C2:C1020,B12) -> 26 | D12: =C12/SUM($C$5:$C$26) -> 0.025515211
B13: Alimentação | C13: =COUNTIF('Base Completa'!C2:C1020,B13) -> 25 | D13: =C13/SUM($C$5:$C$26) -> 0.024533857
B14: Serviços Gerais | C14: =COUNTIF('Base Completa'!C2:C1020,B14) -> 20 | D14: =C14/SUM($C$5:$C$26) -> 0.019627085
B15: Moda Masculina | C15: =COUNTIF('Base Completa'!C2:C1020,B15) -> 19 | D15: =C15/SUM($C$5:$C$26) -> 0.018645731
B16: Outros / Diversos | C16: =COUNTIF('Base Completa'!C2:C1020,B16) -> 18 | D16: =C16/SUM($C$5:$C$26) -> 0.017664377
B17: Moda Infantil / Juvenil | C17: =COUNTIF('Base Completa'!C2:C1020,B17) -> 13 | D17: =C17/SUM($C$5:$C$26) -> 0.012757605
B18: Brinquedos e Games | C18: =COUNTIF('Base Completa'!C2:C1020,B18) -> 13 | D18: =C18/SUM($C$5:$C$26) -> 0.012757605
B19: Moda Fitness | C19: =COUNTIF('Base Completa'!C2:C1020,B19) -> 8 | D19: =C19/SUM($C$5:$C$26) -> 0.0078508342
B20: Moda Praia | C20: =COUNTIF('Base Completa'!C2:C1020,B20) -> 6 | D20: =C20/SUM($C$5:$C$26) -> 0.0058881256
B21: Decoração e Casa | C21: =COUNTIF('Base Completa'!C2:C1020,B21) -> 6 | D21: =C21/SUM($C$5:$C$26) -> 0.0058881256
B22: Moda Íntima | C22: =COUNTIF('Base Completa'!C2:C1020,B22) -> 4 | D22: =C22/SUM($C$5:$C$26) -> 0.0039254171
B23: Moda Festa | C23: =COUNTIF('Base Completa'!C2:C1020,B23) -> 4 | D23: =C23/SUM($C$5:$C$26) -> 0.0039254171
B24: Embalagens, Expositores e Manequins | C24: =COUNTIF('Base Completa'!C2:C1020,B24) -> 3 | D24: =C24/SUM($C$5:$C$26) -> 0.0029440628
B25: Moda Evangélica | C25: =COUNTIF('Base Completa'!C2:C1020,B25) -> 2 | D25: =C25/SUM($C$5:$C$26) -> 0.0019627085
B26: Tecidos e Retalhos | C26: =COUNTIF('Base Completa'!C2:C1020,B26) -> 1 | D26: =C26/SUM($C$5:$C$26) -> 0.00098135427
B27: TOTAL | C27: =SUM(C5:C26) -> 1019

Sheet Painel por Polo
B2: Fornecedores por Polo / Shopping
B4: Polo / Shopping | C4: Fornecedores | D4: % da Base
B5: Galeria Pagé | C5: =COUNTIF('Base Completa'!E2:E1020,B5) -> 287 | D5: =C5/SUM($C$5:$C$10) -> 0.28164868
B6: Shopping Total Brás | C6: =COUNTIF('Base Completa'!E2:E1020,B6) -> 255 | D6: =C6/SUM($C$5:$C$10) -> 0.25024534
B7: Shopping Canindé | C7: =COUNTIF('Base Completa'!E2:E1020,B7) -> 193 | D7: =C7/SUM($C$5:$C$10) -> 0.18940137
B8: Shopping Porto Brás | C8: =COUNTIF('Base Completa'!E2:E1020,B8) -> 157 | D8: =C8/SUM($C$5:$C$10) -> 0.15407262
B9: Shopping All Brás | C9: =COUNTIF('Base Completa'!E2:E1020,B9) -> 105 | D9: =C9/SUM($C$5:$C$10) -> 0.1030422
B10: O Melhor do Brás (Diretório) | C10: =COUNTIF('Base Completa'!E2:E1020,B10) -> 22 | D10: =C10/SUM($C$5:$C$10) -> 0.021589794
B11: TOTAL | C11: =SUM(C5:C10) -> 1019

Sheet Base Completa
A1: Nº | B1: Loja / Fornecedor | C1: Categoria | D1: Segmento Original (fonte) | E1: Polo / Shopping | F1: WhatsApp | G1: Instagram | H1: Site / Link da Loja | I1: Observação (unidade/endereço)
A2: 1 | B2: 2L | C2: Moda Feminina | D2: Moda Feminina | E2: Shopping Total Brás | F2: Abrir WhatsApp | G2: @2l.oficial | H2: Ver loja
A3: 2 | B3: 3 Marias | C3: Moda Feminina | D3: Moda Feminina | E3: Shopping Total Brás | F3: Abrir WhatsApp | G3: @3marias.oficial | H3: Ver loja
A4: 3 | B4: 4Elementos | C4: Moda Feminina | D4: Moda Feminina | E4: Shopping Total Brás | F4: Abrir WhatsApp | G4: @4elementos_28 | H4: Ver loja
A5: 4 | B5: 775 | C5: Acessórios e Bijuterias | D5: Acessórios | E5: Shopping Total Brás | F5: Abrir WhatsApp | G5: @775.oculos | H5: Ver loja
A6: 5 | B6: A BRABA | C6: Moda Feminina | D6: Moda Feminina | E6: Shopping Total Brás | F6: Abrir WhatsApp | G6: @brabaoficialmodas | H6: Ver loja
A7: 6 | B7: A Criativa | C7: Moda Feminina | D7: Moda Feminina | E7: Shopping Total Brás | F7: Abrir WhatsApp | G7: @acriativamodasbras | H7: Ver loja
A8: 7 | B8: A.R JEANS | C8: Moda Infantil / Juvenil | D8: Moda Infantil | E8: Shopping Total Brás | F8: Abrir WhatsApp | G8: @arjeans_oficial | H8: Ver loja
A9: 8 | B9: ABSOLUX JEANS | C9: Moda Jeans | D9: Moda Jeans | E9: Shopping Total Brás | F9: Abrir WhatsApp | G9: @absoluxjeans | H9: Ver loja
A10: 9 | B10: Achados e Perdidos | C10: Moda Feminina | D10: Moda Feminina | E10: Shopping Total Brás | F10: Abrir WhatsApp | G10: @achadoseperdidosestilo | H10: Ver loja
A11: 10 | B11: ADORA | C11: Moda Feminina | D11: Moda Feminina | E11: Shopping Total Brás | F11: Abrir WhatsApp | G11: @adora_oficial | H11: Ver loja
A12: 11 | B12: AESTILOSA | C12: Moda Feminina | D12: Moda Feminina | E12: Shopping Total Brás | F12: Abrir WhatsApp | G12: @aestilosaoficial_bytatimartins | H12: Ver loja
A13: 12 | B13: AFETTO | C13: Moda Feminina | D13: Moda Feminina | E13: Shopping Total Brás | F13: Abrir WhatsApp | G13: @afettomodas | H13: Ver loja
... A40: 39 | B40: D&M STORE | C40: Moda Feminina | D40: Moda Feminina | E40: Shopping Total Brás | F40: Abrir WhatsApp | G40: @lojad.m_store | H40: Ver loja
A41: 40 | B41: D.Na | C41: Moda Feminina | D41: Moda Feminina | E41: Shopping Total Brás | F41: Abrir WhatsApp | H41: Ver loja
A42: 41 | B42: Dafanda | C42: Moda Feminina | D42: Moda Feminina | E42: Shopping Total Brás | F42: Abrir WhatsApp | G42: @dafandabras | H42: Ver loja
A43: 42 | B43: DAJAQUE ATACADO | C43: Moda Feminina | D43: Moda Feminina | E43: Shopping Total Brás | F43: Abrir WhatsApp | G43: @dajaqueatacado | H43: Ver loja
A44: 43 | B44: Dan Dan | C44: Moda Feminina | D44: Moda Feminina | E44: Shopping Total Brás | F44: Abrir WhatsApp | G44: @dandanmoda | H44: Ver loja
A45: 44 | B45: Dandan | C45: Moda Feminina | D45: Moda Feminina | E45: Shopping Total Brás | F45: Abrir WhatsApp | G45: @dandanmoda | H45: Ver loja
A46: 45 | B46: D´Amos | C46: Moda Feminina | D46: Moda Feminina | E46: Shopping Total Brás | F46: Abrir WhatsApp | G46: @modas_de_amos | H46: Ver loja
A47: 46 | B47: D’ Luxo | C47: Moda Feminina | D47: Moda Feminina | E47: Shopping Total Brás | F47: Abrir WhatsApp | G47: @dluxomodas_ | H47: Ver loja
A48: 47 | B48: D’Amos | C48: Moda Feminina | D48: Moda Feminina | E48: Shopping Total Brás | F48: Abrir WhatsApp | G48: @modas_de_amos | H48: Ver loja
A49: 48 | B49: D’bela | C49: Moda Feminina | D49: Moda Feminina | E49: Shopping Total Brás | F49: Abrir WhatsApp | G49: @dbelaa | H49: Ver loja
A50: 49 | B50: D’Ismael | C50: Moda Feminina | D50: Moda Feminina | E50: Shopping Total Brás | F50: Abrir WhatsApp | G50: @d_ismaelmodas | H50: Ver loja
A51: 50 | B51: D’Ismael | C51: Moda Feminina | D51: Moda Feminina | E51: Shopping Total Brás | F51: Abrir WhatsApp | G51: @d_ismaelmodas | H51: Ver loja
A52: 51 | B52: E Fashion | C52: Moda Feminina | D52: Moda Feminina | E52: Shopping Total Brás | F52: Abrir WhatsApp | G52: @e.fashion_oficial | H52: Ver loja
A53: 52 | B53: Eclética Z | C53: Moda Feminina | D53: Moda Feminina | E53: Shopping Total Brás | F53: Abrir WhatsApp | G53: @ecletica_z | H53: Ver loja
... A103: 102 | B103: Irreverente | C103: Moda Feminina | D103: Moda Feminina | E103: Shopping Total Brás | F103: Abrir WhatsApp | G103: @irrev.modas | H103: Ver loja
A104: 103 | B104: Iruma | C104: Moda Feminina | D104: Moda Feminina | E104: Shopping Total Brás | F104: Abrir WhatsApp | H104: Ver loja
A105: 104 | B105: It Curves | C105: Moda Feminina | D105: Moda Feminina | E105: Shopping Total Brás | F105: Abrir WhatsApp | G105: @itcurves | H105: Ver loja
A106: 105 | B106: Jaja Modas | C106: Moda Feminina | D106: Moda Feminina | E106: Shopping Total Brás | F106: Abrir WhatsApp | G106: @jaja_modas | H106: Ver loja
A107: 106 | B107: Jasming Plus | C107: Moda Feminina Plus Size | D107: Moda Plus Size | E107: Shopping Total Brás | F107: Abrir WhatsApp | G107: @jasming.plus | H107: Ver loja
A108: 107 | B108: Jilem Modas | C108: Moda Feminina | D108: Moda Feminina | E108: Shopping Total Brás | F108: Abrir WhatsApp | G108: @jilem_modas | H108: Ver loja
A109: 108 | B109: JIS MODAS | C109: Moda Feminina | D109: Moda Feminina | E109: Shopping Total Brás | F109: Abrir WhatsApp | G109: @jismodas_total | H109: Ver loja
A110: 109 | B110: JK JENNY KIM | C110: Moda Feminina | D110: Moda Feminina | E110: Shopping Total Brás | F110: Abrir WhatsApp | G110: @jennykim.oficial | H110: Ver loja
A111: 110 | B111: JOIAS FORMEHEL | C111: Acessórios e Bijuterias | D111: Acessórios | E111: Shopping Total Brás | F111: Abrir WhatsApp | G111: @joiasformehel | H111: Ver loja
A112: 111 | B112: JOWY | C112: Moda Fitness | D112: Moda Fitness | E112: Shopping Total Brás | F112: Abrir WhatsApp | G112: @jowy.modas | H112: Ver loja
A113: 112 | B113: JOÁ | C113: Moda Feminina | D113: Moda Feminina | E113: Shopping Total Brás | F113: Abrir WhatsApp | G113: @joa.trendsatacado | H113: Ver loja
A114: 113 | B114: JP Perfumes Importados | C114: Perfumaria e Cosméticos | D114: Perfumes | E114: Shopping Total Brás | F114: Abrir WhatsApp | G114: @jpperfumesimportsorig | H114: Ver loja
A115: 114 | B115: JSP MODAS | C115: Moda Feminina | D115: Moda Feminina | E115: Shopping Total Brás | F115: Abrir WhatsApp | G115: @jspmodafeminina | H115: Ver loja
...

Sheet Total Brás
A1: Shopping Total Brás — 255 fornecedores mapeados
A2: Nº | B2: Loja / Fornecedor | C2: Categoria | D2: WhatsApp | E2: Instagram | F2: Site / Link | G2: Observação
A3: 1 | B3: 2L | C3: Moda Feminina | D3: Abrir WhatsApp | E3: @2l.oficial | F3: Ver loja
A4: 2 | B4: 3 Marias | C4: Moda Feminina | D4: Abrir WhatsApp | E4: @3marias.oficial | F4: Ver loja
A5: 3 | B5: 4Elementos | C5: Moda Feminina | D5: Abrir WhatsApp | E5: @4elementos_28 | F5: Ver loja
A6: 4 | B6: 775 | C6: Acessórios e Bijuterias | D6: Abrir WhatsApp | E6: @775.oculos | F6: Ver loja
A7: 5 | B7: A BRABA | C7: Moda Feminina | D7: Abrir WhatsApp | E7: @brabaoficialmodas | F7: Ver loja
A8: 6 | B8: A Criativa | C8: Moda Feminina | D8: Abrir WhatsApp | E8: @acriativamodasbras | F8: Ver loja
A9: 7 | B9: A.R JEANS | C9: Moda Infantil / Juvenil | D9: Abrir WhatsApp | E9: @arjeans_oficial | F9: Ver loja
A10: 8 | B10: ABSOLUX JEANS | C10: Moda Jeans | D10: Abrir WhatsApp | E10: @absoluxjeans | F10: Ver loja
A11: 9 | B11: Achados e Perdidos | C11: Moda Feminina | D11: Abrir WhatsApp | E11: @achadoseperdidosestilo | F11: Ver loja
A12: 10 | B12: ADORA | C12: Moda Feminina | D12: Abrir WhatsApp | E12: @adora_oficial | F12: Ver loja
A13: 11 | B13: AESTILOSA | C13: Moda Feminina | D13: Abrir WhatsApp | E13: @aestilosaoficial_bytatimartins | F13: Ver loja
A14: 12 | B14: AFETTO | C14: Moda Feminina | D14: Abrir WhatsApp | E14: @afettomodas | F14: Ver loja
... A41: 39 | B41: D&M STORE | C41: Moda Feminina | D41: Abrir WhatsApp | E41: @lojad.m_store | F41: Ver loja
A42: 40 | B42: D.Na | C42: Moda Feminina | D42: Abrir WhatsApp | F42: Ver loja
A43: 41 | B43: Dafanda | C43: Moda Feminina | D43: Abrir WhatsApp | E43: @dafandabras | F43: Ver loja
A44: 42 | B44: DAJAQUE ATACADO | C44: Moda Feminina | D44: Abrir WhatsApp | E44: @dajaqueatacado | F44: Ver loja
A45: 43 | B45: Dan Dan | C45: Moda Feminina | D45: Abrir WhatsApp | E45: @dandanmoda | F45: Ver loja
A46: 44 | B46: Dandan | C46: Moda Feminina | D46: Abrir WhatsApp | E46: @dandanmoda | F46: Ver loja
A47: 45 | B47: D´Amos | C47: Moda Feminina | D47: Abrir WhatsApp | E47: @modas_de_amos | F47: Ver loja
A48: 46 | B48: D’ Luxo | C48: Moda Feminina | D48: Abrir WhatsApp | E48: @dluxomodas_ | F48: Ver loja
A49: 47 | B49: D’Amos | C49: Moda Feminina | D49: Abrir WhatsApp | E49: @modas_de_amos | F49: Ver loja
A50: 48 | B50: D’bela | C50: Moda Feminina | D50: Abrir WhatsApp | E50: @dbelaa | F50: Ver loja
A51: 49 | B51: D’Ismael | C51: Moda Feminina | D51: Abrir WhatsApp | E51: @d_ismaelmodas | F51: Ver loja
A52: 50 | B52: D’Ismael | C52: Moda Feminina | D52: Abrir WhatsApp | E52: @d_ismaelmodas | F52: Ver loja
A53: 51 | B53: E Fashion | C53: Moda Feminina | D53: Abrir WhatsApp | E53: @e.fashion_oficial | F53: Ver loja
A54: 52 | B54: Eclética Z | C54: Moda Feminina | D54: Abrir WhatsApp | E54: @ecletica_z | F54: Ver loja
... A104: 102 | B104: Irreverente | C104: Moda Feminina | D104: Abrir WhatsApp | E104: @irrev.modas | F104: Ver loja
A105: 103 | B105: Iruma | C105: Moda Feminina | D105: Abrir WhatsApp | F105: Ver loja
A106: 104 | B106: It Curves | C106: Moda Feminina | D106: Abrir WhatsApp | E106: @itcurves | F106: Ver loja
A107: 105 | B107: Jaja Modas | C107: Moda Feminina | D107: Abrir WhatsApp | E107: @jaja_modas | F107: Ver loja
A108: 106 | B108: Jasming Plus | C108: Moda Feminina Plus Size | D108: Abrir WhatsApp | E108: @jasming.plus | F108: Ver loja
A109: 107 | B109: Jilem Modas | C109: Moda Feminina | D109: Abrir WhatsApp | E109: @jilem_modas | F109: Ver loja
A110: 108 | B110: JIS MODAS | C110: Moda Feminina | D110: Abrir WhatsApp | E110: @jismodas_total | F110: Ver loja
A111: 109 | B111: JK JENNY KIM | C111: Moda Feminina | D111: Abrir WhatsApp | E111: @jennykim.oficial | F111: Ver loja
A112: 110 | B112: JOIAS FORMEHEL | C112: Acessórios e Bijuterias | D112: Abrir WhatsApp | E112: @joiasformehel | F112: Ver loja
A113: 111 | B113: JOWY | C113: Moda Fitness | D113: Abrir WhatsApp | E113: @jowy.modas | F113: Ver loja
A114: 112 | B114: JOÁ | C114: Moda Feminina | D114: Abrir WhatsApp | E114: @joa.trendsatacado | F114: Ver loja
A115: 113 | B115: JP Perfumes Importados | C115: Perfumaria e Cosméticos | D115: Abrir WhatsApp | E115: @jpperfumesimportsorig | F115: Ver loja
...

Sheet Pagé
A1: Galeria Pagé — 287 fornecedores mapeados
A2: Nº | B2: Loja / Fornecedor | C2: Categoria | D2: WhatsApp | E2: Instagram | F2: Site / Link | G2: Observação
A3: 1 | B3: #CHAMA | C3: Eletrônicos e Celulares | D3: Abrir WhatsApp | E3: @hashtagchama | F3: Ver loja
A4: 2 | B4: 3E EAST EMPORIUM ELETRÔNICOS | C4: Eletrônicos e Celulares | D4: Abrir WhatsApp | E4: @3eeastemporium | F4: Ver loja
A5: 3 | B5: 99º C ELETRÔNICOS E ACESSÓRIOS | C5: Eletrônicos e Celulares | D5: Abrir WhatsApp | E5: @99_graus_distribuidora | F5: Ver loja
A6: 4 | B6: AL TANUR | C6: Alimentação | D6: Abrir WhatsApp | E6: @altanur_pagee | F6: Ver loja
A7: 5 | B7: ALAN BRINQUEDOS E ELETRÔNICOS | C7: Brinquedos e Games | D7: Abrir WhatsApp | E7: @alanbrinquedose | F7: Ver loja
A8: 6 | B8: ALEX RELÓGIOS | C8: Relógios e Óculos | D8: Abrir WhatsApp | F8: Ver loja
A9: 7 | B9: ALMEIDA CRUZ | C9: Acessórios e Bijuterias | D9: Abrir WhatsApp | E9: @almeidacruzbr | F9: Ver loja
A10: 8 | B10: ALPHA CASE | C10: Acessórios e Bijuterias | D10: Abrir WhatsApp | E10: @alphacase_65 | F10: Ver loja
A11: 9 | B11: ALÍCIA BIJOUTERIAS | C11: Acessórios e Bijuterias | D11: Abrir WhatsApp | E11: @aliciafolheadoss | F11: Ver loja
A12: 10 | B12: AMAZONA | C12: Perfumaria e Cosméticos | D12: Abrir WhatsApp | E12: @amazonacosmeticosbarbaria | F12: Ver loja
A13: 11 | B13: AMAZONA BARBER SHOP | C13: Serviços Gerais | D13: Abrir WhatsApp | E13: @amazonacosmeticosbarbearia | F13: Ver loja
A14: 12 | B14: AMAZONA HAIR | C14: Serviços Gerais | D14: Abrir WhatsApp | E14: @amazonacosmeticosbarbearia | F14: Ver loja
A15: 13 | B15: ANA ATACADO E VAREJO | C15: Eletrônicos e Celulares | D15: Abrir WhatsApp | E15: @ANJO666888 | F15: Ver loja
A16: 14 | B16: ANNA GRAVAÇÕES | C16: Variedades | D16: Abrir WhatsApp | E16: @. | F16: Ver loja
A17: 15 | B17: AQ SHOPPING | C17: Eletrônicos e Celulares | D17: Abrir WhatsApp | E17: @aq_shopping_1001 | F17: Ver loja
A18: 16 | B18: AROMAPONTOCOM | C18: Perfumaria e Cosméticos | D18: Abrir WhatsApp | E18: @aromaperfumespontocom | F18: Ver loja
A19: 17 | B19: AROMÁTICO | C19: Perfumaria e Cosméticos | D19: Abrir WhatsApp | E19: @aromatico.br | F19: Ver loja
A20: 18 | B20: ARVORE DO CAFÉ | C20: Alimentação | D20: Abrir WhatsApp | E20: @arvoredocafe2023 | F20: Ver loja
... A25: 23 | B25: AÇAÍ DA JU | C25: Alimentação | D25: Abrir WhatsApp | E25: @acaidaju3216 | F25: Ver loja
A26: 24 | B26: B&W | C26: Eletrônicos e Celulares | D26: Abrir WhatsApp | F26: Ver loja
A27: 25 | B27: BAIHUO CITY ELETRONICOS | C27: Eletrônicos e Celulares | D27: Abrir WhatsApp | E27: @baihuocityeletronicosoficial | F27: Ver loja
A28: 26 | B28: BAM BAM CHICKEN | C28: Alimentação | D28: Abrir WhatsApp | E28: @bambam_chickenbras | F28: Ver loja
A29: 27 | B29: BAZAR JOINHA | C29: Eletrônicos e Celulares | D29: Abrir WhatsApp | E29: @bazar.joinha | F29: Ver loja
A30: 28 | B30: BEIRUT CAPAS | C30: Acessórios e Bijuterias | D30: Abrir WhatsApp | E30: @beirutcapas | F30: Ver loja
A31: 29 | B31: BELLE VIE | C31: Relógios e Óculos | D31: Abrir WhatsApp | E31: @belleviebras | F31: Ver loja
A32: 30 | B32: BENEDO | C32: Eletrônicos e Celulares | D32: Abrir WhatsApp | E32: @benedo_relogios | F32: Ver loja
A33: 31 | B33: BEST SHOP | C33: Eletrônicos e Celulares | D33: Abrir WhatsApp | E33: @spbestshop | F33: Ver loja
A34: 32 | B34: BG BRINQUEDOS | C34: Brinquedos e Games | D34: Abrir WhatsApp | E34: @bg.brinquedos | F34: Ver loja
A35: 33 | B35: BIANCA | C35: Relógios e Óculos | D35: Abrir WhatsApp | F35: Ver loja
A36: 34 | B36: BLACK STORY | C36: Eletrônicos e Celulares | D36: Abrir WhatsApp | E36: @blackstory_oficial | F36: Ver loja
A37: 35 | B37: BOM & BARATO | C37: Eletrônicos e Celulares | D37: Abrir WhatsApp | E37: @. | F37: Ver loja
A38: 36 | B38: BOX 1124/1125 | C38: Eletrônicos e Celulares | D38: Abrir WhatsApp | E38: @panda835799 | F38: Ver loja
A39: 37 | B39: BTV LIVE | C39: Eletrônicos e Celulares | D39: Abrir WhatsApp | E39: @oficial.btvlive | F39: Ver loja
A40: 38 | B40: BURGUER KING | C40: Alimentação | D40: Abrir WhatsApp | F40: Ver loja
A41: 39 | B41: BURGUER KING - Q | C41: Alimentação | D41: Abrir WhatsApp | E41: @. | F41: Ver loja
A42: 40 | B42: C&Y | C42: Perfumaria e Cosméticos | D42: Abrir WhatsApp | E42: @artedeunha_olinrovi | F42: Ver loja
A43: 41 | B43: C.C ATACADO E VAREJO | C43: Acessórios e Bijuterias | D43: Abrir WhatsApp | F43: Ver loja
A44: 42 | B44: CAMILA RELÓGIOS | C44: Relógios e Óculos | D44: Abrir WhatsApp | E44: @camila.relogios | F44: Ver loja
...

Sheet Canindé
A1: Shopping Canindé — 193 fornecedores mapeados
A2: Nº | B2: Loja / Fornecedor | C2: Categoria | D2: WhatsApp | E2: Instagram | F2: Site / Link | G2: Observação
A3: 1 | B3: AF MODA FESTA | C3: Moda Feminina | D3: Abrir WhatsApp | E3: @af_modafesta | F3: Ver loja
A4: 2 | B4: AGUERO MODAS / AGUERO PREMIUM | C4: Moda Feminina | D4: Abrir WhatsApp | E4: @wr.%20aguero%20wr.aguero%20premium | F4: Ver loja
A5: 3 | B5: AGUERO MODAS / AGUERO PREMIUM | C5: Moda Feminina | D5: Abrir WhatsApp | E5: @wr.%20aguero%20wr.aguero%20premium | F5: Ver loja
A6: 4 | B6: AL MODASS | C6: Moda Feminina | D6: Abrir WhatsApp | E6: @almodass_ | F6: Ver loja
A7: 5 | B7: ALASKA | C7: Moda Feminina | D7: Abrir WhatsApp | E7: @alaska_jeans | F7: Ver loja
A8: 6 | B8: ALASKA ATACADO | C8: Moda Feminina | D8: Abrir WhatsApp | E8: @alaskaatacado | F8: Ver loja
A9: 7 | B9: ALEIDA MODAS | C9: Moda Feminina | D9: Abrir WhatsApp | E9: @alaidamodastricos | F9: Ver loja
A10: 8 | B10: ALEX WINSTON | C10: Moda Feminina | D10: Abrir WhatsApp | E10: @alexis_wmodas | F10: Ver loja
A11: 9 | B11: ALL KISS STORE | C11: Moda Feminina | D11: Abrir WhatsApp | E11: @allkiss.store | F11: Ver loja
A12: 10 | B12: AMING MODAS | C12: Moda Feminina | D12: Abrir WhatsApp | E12: @a.mingjeans | F12: Ver loja
A13: 11 | B13: AMING MODAS ATACADO E VAREJO | C13: Moda Jeans | D13: Abrir WhatsApp | E13: @a.mingjeans | F13: Ver loja
A14: 12 | B14: ANDREA & ALEXANDRE | C14: Moda Feminina | D14: Abrir WhatsApp | E14: @andreaealexandrastore | F14: Ver loja
... A46: 44 | B46: DONA JENAS PREMIUM DELUXE | C46: Moda Jeans | D46: Abrir WhatsApp | E46: @donajeans_atacado | F46: Ver loja
A47: 45 | B47: DONA SEREIA | C47: Variedades | D47: Abrir WhatsApp | F47: Ver loja
A48: 46 | B48: DRIMY FASHION | C48: Moda Feminina | D48: Abrir WhatsApp | E48: @drimy_fashions | F48: Ver loja
A49: 47 | B49: DROGARIA E PERFUMARIA | C49: Variedades | D49: Abrir WhatsApp | F49: Ver loja
A50: 48 | B50: EFRAIM MODAS PLUS SIZE | C50: Moda Feminina Plus Size | D50: Abrir WhatsApp | E50: @efraimmodasplus | F50: Ver loja
A51: 49 | B51: ELIBELLE MODAS | C51: Moda Feminina | D51: Abrir WhatsApp | E51: @elibelle.modas | F51: Ver loja
A52: 50 | B52: ELICA | C52: Moda Feminina | D52: Abrir WhatsApp | E52: @elica_495 | F52: Ver loja
A53: 51 | B53: ELSA RAMIRESS | C53: Moda Feminina | D53: Abrir WhatsApp | E53: @elsaramiress | F53: Ver loja
A54: 52 | B54: EMILY MODAS | C54: Moda Feminina Plus Size | D54: Abrir WhatsApp | E54: @emilyplussizee | F54: Ver loja
A55: 53 | B55: ESTAÇÃO BRASIL | C55: Moda Feminina | D55: Abrir WhatsApp | E55: @estacao_brasil_ | F55: Ver loja
A56: 54 | B56: ESTILO BLOGUEIRINHA | C56: Moda Feminina | D56: Abrir WhatsApp | E56: @estilo%20blogueirinhaa_ | F56: Ver loja
A57: 55 | B57: ETIQUETA ROSA | C57: Moda Feminina | D57: Abrir WhatsApp | E57: @loja%20etiquera%20rosa | F57: Ver loja
A58: 56 | B58: EXCLUSIVA JEANS | C58: Moda Jeans | D58: Abrir WhatsApp | E58: @exclusivajeans_ | F58: Ver loja
A59: 57 | B59: FLOR IS BELLA | C59: Moda Feminina | D59: Abrir WhatsApp | E59: @flor_is_bellastore | F59: Ver loja
A60: 58 | B60: FLOR VICTÓRIA | C60: Moda Feminina | D60: Abrir WhatsApp | E60: @florvictoria | F60: Ver loja
A61: 59 | B61: FOFA MODA | C61: Variedades | F61: Ver loja
A62: 60 | B62: GT KIDS | C62: Moda Infantil / Juvenil | D62: Abrir WhatsApp | E62: @gt.kids | F62: Ver loja
A63: 61 | B63: GURIA OUSADA | C63: Moda Feminina | D63: Abrir WhatsApp | E63: @guriaousada_bras | F63: Ver loja
A64: 62 | B64: H B FASHION | C64: Moda Feminina | D64: Abrir WhatsApp | E64: @hbfashion_oficial | F64: Ver loja
A65: 63 | B65: H CAT ATACADO | C65: Moda Feminina | D65: Abrir WhatsApp | E65: @hcat.atacado | F65: Ver loja
A66: 64 | B66: H&H MODAS | C66: Moda Feminina | D66: Abrir WhatsApp | E66: @hh_modas | F66: Ver loja
A67: 65 | B67: HAIDAR JAQUETAS | C67: Moda Feminina | D67: Abrir WhatsApp | E67: @haidar%20jaquetas | F67: Ver loja
A68: 66 | B68: HANDOU ZHANG | C68: Moda Feminina | D68: Abrir WhatsApp | E68: @handouzhang9 | F68: Ver loja
A69: 67 | B69: HELLEN | C69: Moda Feminina | D69: Abrir WhatsApp | E69: @hellen.modaas | F69: Ver loja
A70: 68 | B70: IF STORE MODA FEMININA | C70: Moda Feminina | D70: Abrir WhatsApp | E70: @ifstoretshirt | F70: Ver loja
A71: 69 | B71: INTRUSO ESTILO FEMININO | C71: Moda Feminina Plus Size | D71: Abrir WhatsApp | E71: @intrusomodas | F71: Ver loja
...

Sheet Porto Brás
A1: Shopping Porto Brás — 157 fornecedores mapeados
A2: Nº | B2: Loja / Fornecedor | C2: Categoria | D2: WhatsApp | E2: Instagram | F2: Site / Link | G2: Observação
A3: 1 | B3: A.K.D Moda Infantil E Adulto | C3: Moda Infantil / Juvenil | D3: Abrir WhatsApp | E3: @akd modas / vellamariamodasinfantil
A4: 2 | B4: Alan | C4: Moda Feminina | D4: Abrir WhatsApp | E4: @zhang663311
A5: 3 | B5: Ali Burguer | C5: Alimentação | D5: Abrir WhatsApp
A6: 4 | B6: Alto Stilo | C6: Moda Jeans | D6: Abrir WhatsApp | E6: @alto_stilo_imports
A7: 5 | B7: Amin Jeans | C7: Moda Jeans | D7: Abrir WhatsApp | E7: @amin_jeans
A8: 6 | B8: Ana Fashion | C8: Moda Feminina | D8: Abrir WhatsApp | E8: @ana.xiaofeng.liu
A9: 7 | B9: Antonio Agostinho Ribeiro | C9: Alimentação
A10: 8 | B10: Arco Íris Da Garoa | C10: Serviços Gerais | D10: Abrir WhatsApp | E10: @arcoirisdagaroa
A11: 9 | B11: Areen Plus | C11: Moda Feminina Plus Size | D11: Abrir WhatsApp | E11: @areenplus
A12: 10 | B12: Bamboo | C12: Moda Feminina | D12: Abrir WhatsApp | E12: @loja_bamboo
A13: 11 | B13: Bb Jeans | C13: Moda Jeans | E13: @b.b_jeans1
A14: 12 | B14: Bd Jeans | C14: Moda Jeans | D14: Abrir WhatsApp | E14: @bdjeans.sp
A15: 13 | B15: Bds Jeans Fashion | C15: Moda Jeans | D15: Abrir WhatsApp | E15: @marufabadin / neofashion-22
A16: 14 | B16: Bela Plus | C16: Moda Feminina Plus Size | D16: Abrir WhatsApp | E16: @belaplus.oficial
A17: 15 | B17: Bela Rosê Atacado | C17: Moda Feminina | E17: @bella_rose2017
A18: 16 | B18: Bijuterias Carmem | C18: Acessórios e Bijuterias | D18: Abrir WhatsApp | E18: @carmenbijuterias35
A19: 17 | B19: Blue Cherry Jeans | C19: Moda Jeans | D19: Abrir WhatsApp | E19: @Bluecherryjeans
A20: 18 | B20: Boneco Cobertores | C20: Decoração e Casa | E20: @bonecocobertores404
A21: 19 | B21: Box 319 / 320 | C21: Moda Feminina | D21: Abrir WhatsApp | E21: @calcamenina319
A22: 20 | B22: Box 374 / 375 – Óculos | C22: Relógios e Óculos | D22: Abrir WhatsApp
A23: 21 | B23: Box 53 | C23: Moda Praia | D23: Abrir WhatsApp | E23: @maria porto bras 53
A24: 22 | B24: Box 54 | C24: Moda Feminina | D24: Abrir WhatsApp | E24: @egligi / charlote_fashion99
A25: 23 | B25: Box 60 E 62 | C25: Moda Feminina | D25: Abrir WhatsApp | E25: @jennyxu815
A26: 24 | B26: Bruna Moda Feminina | C26: Moda Feminina | D26: Abrir WhatsApp | E26: @br.una8360
A27: 25 | B27: Byung Atacado Modas | C27: Moda Feminina | D27: Abrir WhatsApp
A28: 26 | B28: C Y-Sir | C28: Moda Feminina | D28: Abrir WhatsApp | E28: @ti.ng2895
A29: 27 | B29: Camila Alves Dos Santos | C29: Moda Feminina | E29: @puro_estiloelegante
A30: 28 | B30: Casa Das Embalagens | C30: Outros / Diversos | D30: Abrir WhatsApp | E30: @casadasembalagensbras
A31: 29 | B31: Cattleya | C31: Moda Jeans | D31: Abrir WhatsApp | E31: @cattleya_lojaofficial
A32: 30 | B32: Celina Modas | C32: Moda Feminina | D32: Abrir WhatsApp | E32: @celinamodafeminina189
A33: 31 | B33: Changchun Chen Me | C33: Moda Feminina | D33: Abrir WhatsApp | E33: @jin.2360
A34: 32 | B34: Chen Box 304 | C34: Moda Praia
A35: 33 | B35: Dan Moda | C35: Moda Feminina | D35: Abrir WhatsApp | E35: @danmoda.in
A36: 34 | B36: Dhaka Jeans | C36: Moda Jeans | D36: Abrir WhatsApp | E36: @dhakajeans_feminina
A37: 35 | B37: Dien | C37: Moda Feminina | D37: Abrir WhatsApp | E37: @dien.moda
A38: 36 | B38: Dong Dong | C38: Moda Feminina | D38: Abrir WhatsApp | E38: @martaportobras
A39: 37 | B39: Dykas Modinha | C39: Moda Feminina | D39: Abrir WhatsApp | E39: @delpiero_modinhas / kendric_modinhas
A40: 38 | B40: Eliana Confecções | C40: Moda Feminina | E40: @eliana_confeccoes_noemi
...

Sheet All Brás
A1: Shopping All Brás — 105 fornecedores mapeados
A2: Nº | B2: Loja / Fornecedor | C2: Categoria | D2: WhatsApp | E2: Instagram | F2: Site / Link | G2: Observação
A3: 1 | B3: ABIGAIL HAULEY MODAS | C3: Moda Feminina | D3: Abrir WhatsApp | E3: @abigailmodas8 | G3: Loja 1069
A4: 2 | B4: ADRI CONFECÇÕES | C4: Moda Feminina Plus Size | D4: Abrir WhatsApp | E4: @adri_confeccoes1055 | G4: Loja 1055
A5: 3 | B5: ALYAA MODAS | C5: Moda Feminina | D5: Abrir WhatsApp | E5: @aliaamodas | G5: Loja 1088
A6: 4 | B6: AY | C6: Moda Feminina Plus Size | D6: Abrir WhatsApp | E6: @celina.ayala.3139 | G6: Loja 1043
A7: 5 | B7: BENTA FLOR | C7: Moda Feminina | D7: Abrir WhatsApp | E7: @benta_flor | G7: Loja 1053
A8: 6 | B8: BETO CONFECÇÕES | C8: Moda Feminina Plus Size | D8: Abrir WhatsApp | E8: @mary_i_s_r | G8: Loja 1027
A9: 7 | B9: BRITANNY FASHION | C9: Moda Feminina | D9: Abrir WhatsApp | E9: @brittany_fashion_plus_size | G9: Loja 1120
A10: 8 | B10: C . TAMARA CONFECÇÕES | C10: Moda Feminina | D10: Abrir WhatsApp | E10: @c.tamaramodas | G10: Loja 1139
A11: 9 | B11: CHEEKY COFECÇÕES | C11: Moda Feminina Plus Size | D11: Abrir WhatsApp | G11: Loja 1091
A12: 10 | B12: CONFECÇOES GABRIELA | C12: Moda Feminina | D12: Abrir WhatsApp | E12: @confeccoes.gabriela | G12: Loja 1107-A
A13: 11 | B13: CONFECÇOES JKM | C13: Moda Feminina | D13: Abrir WhatsApp | E13: @tania.marca.12 | G13: Loja 1056
A14: 12 | B14: CONFECÇÕES ARIAS | C14: Moda Feminina Plus Size | D14: Abrir WhatsApp | E14: @moda_arias | G14: Loja 1052
A15: 13 | B15: CONFECÇÕES CARMEN | C15: Moda Feminina | D15: Abrir WhatsApp | E15: @carmen_confeccoes | G15: Loja 1118
A16: 14 | B16: CONFECÇÕES CELESTE | C16: Moda Feminina | D16: Abrir WhatsApp | E16: @confeccoes_celeste | G16: Loja 1106
A17: 15 | B17: CONFECÇÕES DAISO-GIJO | C17: Moda Feminina | D17: Abrir WhatsApp | E17: @daisa_gijo | G17: Loja 1054
A18: 16 | B18: CONFECÇÕES DAMARIS | C18: Moda Feminina | D18: Abrir WhatsApp | E18: @plusdamaris | G18: Loja 1099
A19: 17 | B19: CONFECÇÕES F.L | C19: Moda Feminina | D19: Abrir WhatsApp | E19: @flconfeccoess | G19: Loja 1137
A20: 18 | B20: CONFECÇÕES FLORESNAT | C20: Moda Feminina Plus Size | D20: Abrir WhatsApp | E20: @floresnatatacado | G20: Loja 1046
A21: 19 | B21: CONFECÇÕES FLOWERS | C21: Moda Feminina Plus Size | D21: Abrir WhatsApp | E21: @abigailmodas8 | G21: Loja 1071
A22: 20 | B22: CONFECÇÕES GABRIELA | C22: Moda Feminina Plus Size | D22: Abrir WhatsApp | E22: @confeccoes.gabriela | G22: Loja 1107A
A23: 21 | B23: CONFECÇÕES KETAL | C23: Moda Feminina Plus Size | D23: Abrir WhatsApp | G23: Loja 1087
A24: 22 | B24: CONFECÇÕES LUIS | C24: Moda Feminina | D24: Abrir WhatsApp | E24: @confeccoes_luis | G24: Loja 1026
A25: 23 | B25: CONFECÇÕES LUIS | C25: Moda Feminina | D25: Abrir WhatsApp | G25: Loja 1094
A26: 24 | B26: CONFECÇÕES MELISSA | C26: Moda Feminina | D26: Abrir WhatsApp | G26: Loja 1057
A27: 25 | B27: CONFECÇÕES MOISES | C27: Moda Feminina Plus Size | D27: Abrir WhatsApp | E27: @confeciones_moises | G27: Loja 1132
A28: 26 | B28: CONFECÇÕES SANGA | C28: Moda Feminina Plus Size | D28: Abrir WhatsApp | E28: @confeccoes_sanga | G28: Loja 1063
A29: 27 | B29: CONFECÇÕES SML | C29: Moda Feminina Plus Size | D29: Abrir WhatsApp | E29: @samuelyquisi | G29: Loja 1050
A30: 28 | B30: DANIELA ARTESANATOS | C30: Acessórios e Bijuterias | D30: Abrir WhatsApp | E30: @daniela_artesanatos | G30: Loja 1278
A31: 29 | B31: DEEVANI CONFECÇÕES | C31: Moda Feminina | D31: Abrir WhatsApp | E31: @deevaniconfecções | G31: Loja 1147
A32: 30 | B32: DENNNER CONFECÇÕES | C32: Moda Feminina | D32: Abrir WhatsApp | E32: @denner.modas | G32: Loja 1100
A33: 31 | B33: DIVAN LANCHES E PASTEIS | C33: Alimentação | D33: Abrir WhatsApp | G33: Loja 1335
A34: 32 | B34: ELVIA CONFECÇÕES | C34: Moda Feminina Plus Size | D34: Abrir WhatsApp | E34: @elvia_confeccoes | G34: Loja 1067
A35: 33 | B35: ESCALANTE | C35: Acessórios e Bijuterias | D35: Abrir WhatsApp | E35: @escalantebijoux | G35: Loja 1079
A36: 34 | B36: ESCALANTE BIJOUX | C36: Acessórios e Bijuterias | D36: Abrir WhatsApp | E36: @escalantebijoux | G36: Loja 1108
A37: 35 | B37: EXCLUSIVA BELA | C37: Moda Feminina Plus Size | D37: Abrir WhatsApp | E37: @exclusivabella_plus | G37: Loja 1104
A38: 36 | B38: FARID-E MODAS | C38: Moda Feminina Plus Size | D38: Abrir WhatsApp | E38: @fari_dmodas | G38: Loja 1133
A39: 37 | B39: FARMÁCIA POUPE MAIS | C39: Serviços Gerais | D39: Abrir WhatsApp | E39: @poupemaisdrogarias | G39: Loja 1005
A40: 38 | B40: FINA FLOR | C40: Moda Feminina | D40: Abrir WhatsApp | E40: @finaflor_outlet | G40: Loja 1119
...

Sheet O Melhor do Brás
A1: O Melhor do Brás (Diretório) — 22 fornecedores mapeados
A2: Nº | B2: Loja / Fornecedor | C2: Categoria | D2: WhatsApp | E2: Instagram | F2: Site / Link | G2: Observação
A3: 1 | B3: ARTCOM VIDROS | C3: Embalagens, Expositores e Manequins | E3: @artcomvidros | F3: Ver loja
A4: 2 | B4: BB VINDO | C4: Moda Infantil / Juvenil | E4: @bb_vindo_oficial | F4: Ver loja
A5: 3 | B5: BRUNFER JEANS | C5: Moda Feminina Plus Size | E5: @brunferjeans | F5: Ver loja
A6: 4 | B6: CASA DAS ARARAS | C6: Embalagens, Expositores e Manequins | E6: @casadasararas | F6: Ver loja
A7: 5 | B7: COMFORTECH | C7: Decoração e Casa | E7: @comfortechbr | F7: Ver loja
A8: 6 | B8: CROCKER JEANS | C8: Moda Jeans | E8: @crocker_jeans | F8: Ver loja
A9: 7 | B9: GOL TÊXTIL | C9: Tecidos e Retalhos | E9: @goltextil_ | F9: Ver loja
A10: 8 | B10: LA SÈVE | C10: Moda Feminina Plus Size | E10: @la_seve_modafeminina | F10: Ver loja
A11: 9 | B11: LOJA CAROLINA BABY | C11: Moda Infantil / Juvenil | F11: Ver loja
A12: 10 | B12: LUMINI JEANS | C12: Moda Jeans | E12: @luminijeans | F12: Ver loja
A13: 11 | B13: LÍQUIDO OUTLET | C13: Moda Fitness | E13: @?hl=pt | F13: Ver loja
A14: 12 | B14: MANI'S CABIDES | C14: Embalagens, Expositores e Manequins | E14: @maniscabidesoficial | F14: Ver loja
A15: 13 | B15: MARIA ALICE MODAS - Plus Size | C15: Moda Feminina Plus Size | E15: @mariaalicemoda757 | F15: Ver loja
A16: 14 | B16: MODA MAZAL - Plus Size | C16: Moda Feminina Plus Size | E16: @moda_mazal | F16: Ver loja
A17: 15 | B17: NEWMAX CONFECÇÕES | C17: Moda Jeans | E17: @confeccoesnewmaxltda | F17: Ver loja
A18: 16 | B18: NIPO CENTER | C18: Moda Festa | E18: @nipocenter | F18: Ver loja
A19: 17 | B19: SHOPPING MEGA POLO MODA | C19: Outros / Diversos | E19: @megapolomoda | F19: Ver loja
A20: 18 | B20: SNAPPER | C20: Moda Masculina | E20: @snapper.co | F20: Ver loja
A21: 19 | B21: STONE WALL | C21: Moda Masculina | E21: @stonewalllojaoficial | F21: Ver loja
A22: 20 | B22: THIPTON | C22: Moda Feminina | E22: @thipton_ | F22: Ver loja
A23: 21 | B23: TUTTO AMORE OFICIAL | C23: Moda Feminina | E23: @tuttoamoreoficial | F23: Ver loja
A24: 22 | B24: UNIBES BAZAR | C24: Moda Infantil / Juvenil | E24: @unibes | F24: Ver loja
